tests/64_threads/sample_61.in
64
o
38 S 101 0 109 687
44 S 102 3 138 89
12 B 103 1 116 457
30 B 104 8 167 262
6 B 106 4 117 155
35 S 107 8 150 416
0 B 108 9 103 500
43 S 110 8 171 74
22 S 111 3 194 94
17 B 112 2 106 196
19 S 113 7 185 94
62 S 114 6 170 715
45 B 116 9 186 576
36 S 117 8 172 352
53 S 118 3 163 456
30 S 119 5 177 911
57 B 121 1 169 352
59 B 122 3 140 457
17 C 112
43 B 125 6 138 180
39 S 126 2 147 196
3 S 127 7 190 885
47 B 130 9 174 473
57 B 131 3 199 410
53 S 133 0 149 864
40 S 136 9 181 600
48 B 137 2 100 244
59 B 138 9 164 81
47 S 139 2 179 522
29 B 140 5 195 393
4 S 141 4 128 883
6 S 142 9 121 920
22 S 143 6 139 792
12 B 144 6 178 313
28 S 145 2 117 950
36 B 146 6 194 118
47 S 147 3 144 924
36 S 148 3 192 633
40 C 136
7 S 150 3 186 332
45 S 151 9 184 389
27 S 152 4 200 569
20 S 153 1 148 738
54 S 154 9 173 771
9 B 157 3 182 284
32 B 159 1 192 487
1 B 160 4 183 103
40 C 136
44 C 102
61 S 165 0 153 966
46 S 166 6 196 915
16 S 167 5 145 57
31 B 168 8 196 643
62 B 169 0 168 112
63 S 170 0 129 992
39 S 172 7 112 932
37 B 174 5 117 160
2 S 175 1 128 628
30 S 176 9 128 61
48 B 177 7 168 486
62 S 178 4 176 997
13 B 179 6 126 542
2 B 180 3 156 972
17 S 181 3 176 174
61 B 182 0 165 652
28 B 183 5 119 850
23 S 184 1 172 47
19 C 113
59 B 186 7 171 549
19 S 187 8 103 960
13 S 188 9 101 556
30 C 104
38 S 190 6 175 535
43 C 110
19 S 192 9 156 667
22 B 193 2 118 793
3 S 194 0 117 632
0 B 195 6 187 67
29 B 196 1 189 760
59 C 122
45 B 198 6 118 879
37 S 199 8 192 938
40 C 136
19 B 202 3 157 995
20 C 153
2 S 204 2 191 194
7 B 206 0 127 162
28 S 207 4 120 140
19 C 202
48 S 209 4 124 564
43 B 210 0 181 422
46 S 211 1 142 869
20 S 213 4 176 874
37 C 199
45 C 116
20 B 217 1 135 893
14 S 218 1 169 127
20 C 217
32 C 159
55 S 221 6 169 766
3 C 194
36 B 223 5 106 401
57 B 224 0 149 699
5 B 225 6 188 877
43 C 110
21 B 227 0 156 93
7 S 228 7 175 490
9 B 229 5 131 552
38 C 101
3 C 194
49 B 232 0 119 113
44 C 102
19 S 234 6 121 864
32 C 159
23 S 236 8 119 425
13 B 237 7 193 152
51 B 238 2 160 250
7 C 150
15 B 241 8 200 828
19 B 243 1 137 529
4 C 141
46 S 246 2 118 442
30 B 247 9 123 734
33 B 249 2 119 29
4 C 141
53 S 251 3 168 472
23 S 252 3 133 853
55 C 221
39 B 254 3 193 105
61 C 165
38 B 256 1 165 30
43 C 210
43 S 258 4 146 852
33 B 259 4 135 529
46 C 246
61 B 261 9 199 880
21 S 262 8 151 336
61 C 182
52 S 264 8 173 885
48 B 265 6 125 718
22 S 266 9 142 412
55 C 221
4 S 268 0 178 963
28 B 269 4 162 93
41 B 270 5 132 374
31 C 168
14 S 272 1 180 69
46 S 273 2 105 825
41 B 274 4 108 447
39 C 172
35 C 107
30 B 277 1 166 801
1 C 160
55 B 279 4 182 454
23 B 280 3 116 780
19 S 281 1 178 944
35 S 282 1 156 921
11 S 283 3 119 121
2 S 284 3 114 456
29 B 285 5 135 148
35 S 286 5 170 174
51 C 238
28 S 288 5 136 209
61 S 289 7 194 867
37 C 174
39 C 172
35 S 292 3 141 573
15 S 293 9 110 766
43 B 294 9 105 563
40 S 295 2 170 809
61 B 296 2 143 265
62 S 297 4 168 38
59 C 122
38 B 299 9 106 14
52 S 300 1 143 200
53 S 301 4 190 431
31 B 302 3 187 27
25 B 303 4 190 381
31 C 168
49 C 232
36 C 146
45 S 307 7 119 614
33 S 308 3 126 23
29 C 196
58 S 310 9 133 392
2 C 204
19 S 312 2 154 214
15 C 293
51 C 238
1 B 315 0 111 652
5 B 316 4 114 340
47 B 317 1 149 16
25 S 318 6 143 943
6 S 319 7 145 103
37 B 320 8 166 533
31 C 168
3 S 322 1 101 211
5 S 323 8 164 96
46 C 246
17 B 325 8 162 421
4 S 326 2 173 168
36 C 223
16 C 167
45 C 307
1 S 330 1 121 916
55 B 331 4 193 420
11 B 332 4 191 746
49 S 333 8 108 847
12 S 334 9 148 374
23 B 335 3 178 384
59 S 336 1 118 415
28 C 183
2 C 175
1 C 160
28 B 340 1 109 494
60 S 341 3 161 205
52 C 264
13 C 179
24 S 344 2 120 740
2 B 345 3 170 558
36 B 346 8 165 286
61 B 347 8 159 300
11 S 348 6 110 264
16 S 349 8 158 450
23 S 350 3 135 327
41 C 274
51 B 352 5 175 92
39 B 353 3 187 829
31 B 354 5 163 951
36 S 355 0 132 854
43 C 110
35 S 357 9 165 243
9 B 358 2 117 539
25 S 359 7 142 94
24 B 360 0 110 269
40 S 361 5 171 701
62 B 362 1 175 554
58 C 310
26 S 364 9 152 312
40 B 365 6 163 844
59 B 366 1 171 96
26 B 367 2 194 405
18 B 368 0 162 220
39 C 353
17 C 112
47 S 371 4 154 406
15 C 241
45 S 373 9 110 43
58 S 374 4 181 552
50 S 375 0 153 564
57 B 376 0 102 983
60 B 377 6 165 724
63 C 170
41 B 379 7 120 605
31 S 380 1 127 527
41 S 381 9 140 724
17 C 181
37 C 199
55 S 384 5 123 682
60 B 385 9 148 273
35 S 386 2 161 783
61 C 347
38 S 388 8 107 368
57 S 389 0 126 636
34 S 390 2 198 854
49 B 391 4 114 605
51 C 352
55 C 221
14 S 394 0 167 937
33 S 396 5 132 436
61 C 182
46 C 273
42 S 399 8 176 641
43 B 400 4 167 675
25 B 401 7 136 11
17 S 403 3 133 364
51 S 404 5 168 388
40 S 405 7 151 215
35 B 406 3 165 128
57 S 407 2 167 817
47 C 139
33 C 259
57 S 410 6 100 262
30 B 411 2 122 849
37 C 320
36 B 413 0 198 789
27 B 414 0 173 867
27 S 415 9 160 321
18 C 368
38 S 417 0 164 205
39 B 418 3 195 250
43 C 258
5 B 420 1 164 89
31 S 421 4 136 544
28 C 207
37 C 320
20 B 424 3 175 901
26 S 425 8 110 975
13 B 426 6 194 674
35 B 427 0 198 42
20 S 428 9 164 339
4 S 429 0 175 42
50 C 375
63 B 431 2 130 791
63 S 432 0 152 676
27 S 433 5 196 947
31 C 168
0 S 435 2 113 911
5 B 436 1 139 846
10 S 437 8 162 383
5 S 438 6 163 409
15 B 439 8 107 248
35 C 292
32 B 441 6 101 70
5 S 442 9 179 740
42 S 443 9 184 683
50 B 444 9 124 276
55 B 445 5 185 438
10 S 446 0 162 100
36 S 447 8 123 819
25 C 359
46 S 449 9 106 652
26 C 425
60 B 451 9 114 884
40 S 452 3 148 57
0 B 454 6 124 279
9 B 455 9 128 375
22 C 143
17 B 457 4 187 829
55 S 458 0 118 291
31 S 459 8 194 600
35 C 282
30 B 461 6 132 741
51 B 462 9 108 667
4 B 463 4 161 181
56 S 464 4 161 771
14 C 218
27 C 414
34 B 467 9 158 555
55 S 468 1 173 374
50 C 444
46 C 246
11 C 348
41 S 472 2 181 133
59 C 122
56 C 464
44 C 102
6 B 476 4 168 955
23 B 477 5 124 535
5 B 478 7 190 952
11 C 348
63 S 480 6 194 296
26 S 481 7 193 356
8 S 482 2 115 560
49 C 232
57 S 484 7 158 158
38 C 190
30 S 486 8 133 212
56 C 464
43 B 488 0 146 242
12 S 489 4 178 800
4 B 490 2 179 395
62 S 491 7 175 510
41 S 492 2 153 50
40 C 136
31 B 494 6 152 170
61 S 495 0 140 319
38 B 496 5 164 305
5 S 497 4 194 357
48 B 498 8 163 576
2 B 499 1 185 764
39 S 500 8 159 442
53 C 133
28 S 502 3 150 159
30 S 503 7 195 874
30 C 277
49 S 505 3 121 577
50 B 506 5 197 297
25 S 507 8 119 900
47 C 147
34 S 509 3 121 129
16 C 349
60 B 511 4 113 917
24 B 512 8 167 470
1 S 513 2 123 802
39 S 514 6 198 477
54 S 515 8 103 637
59 S 516 1 130 757
56 B 517 5 112 571
7 S 518 3 115 927
42 C 399
63 B 520 1 188 363
46 B 521 4 102 168
50 C 375
1 B 523 5 154 174
23 C 280
56 S 525 8 100 738
20 C 428
31 S 527 1 198 279
58 C 310
27 B 529 5 171 334
26 C 364
10 B 531 2 146 352
39 S 532 5 102 675
52 B 533 9 165 824
57 S 534 6 191 744
8 C 482
53 S 536 2 170 877
44 S 537 3 123 302
10 B 538 2 164 24
19 S 539 2 120 165
28 C 145
56 C 464
17 C 325
31 B 543 5 184 745
62 C 491
1 B 545 4 186 876
26 S 546 0 117 127
8 S 547 9 130 274
4 C 429
0 C 435
8 S 550 9 171 522
53 C 536
4 S 552 2 138 425
46 B 553 3 130 549
11 C 283
49 B 555 5 112 204
23 C 236
7 B 557 8 192 855
43 B 558 7 181 218
53 B 559 1 197 177
19 S 560 4 152 296
33 C 259
17 S 562 7 126 934
42 C 443
22 C 111
0 B 565 1 135 30
56 S 566 0 158 477
6 C 106
57 B 568 0 170 997
3 C 194
39 B 570 5 146 544
57 S 571 2 148 819
19 S 572 7 112 985
47 C 139
29 C 285
53 S 575 7 184 795
14 C 272
53 S 577 2 148 970
35 C 357
53 S 579 8 195 21
24 S 580 3 117 291
52 C 533
55 C 331
25 S 583 5 197 394
24 S 584 3 149 432
14 B 585 8 102 629
43 C 400
34 S 587 0 111 846
47 B 588 5 129 15
8 B 589 4 182 347
2 B 590 1 190 210
24 B 591 3 127 604
49 C 505
5 C 323
52 C 533
60 B 595 0 177 885
6 S 596 1 114 805
41 S 597 4 119 52
6 C 476
58 S 599 5 170 527
26 S 600 9 179 633
17 B 601 5 103 515
54 S 602 5 144 202
19 B 603 5 197 698
47 B 604 6 157 619
17 S 605 4 199 769
22 B 606 0 163 744
48 C 265
27 B 608 1 167 871
42 C 443
58 C 374
13 C 188
4 S 612 4 175 196
45 C 151
19 S 614 0 195 794
31 B 615 0 107 951
45 B 616 3 144 974
32 S 617 2 148 91
12 C 489
51 B 619 0 119 112
18 S 620 0 190 420
56 B 621 5 110 947
49 B 622 6 154 478
24 C 344
30 B 624 6 153 870
59 B 625 2 173 477
13 C 426
14 B 627 2 120 243
28 C 183
11 B 629 8 129 114
