tests/64_threads/sample_62.in
64
o
48 B 101 8 158 259
43 B 102 1 171 969
1 B 103 5 115 160
45 B 104 8 198 867
44 S 105 2 137 166
26 B 106 9 143 407
34 B 107 5 163 945
26 C 106
24 S 111 3 107 726
5 B 112 2 170 754
18 S 113 5 189 785
40 B 116 4 106 383
14 B 117 3 172 945
18 B 118 0 109 623
14 C 117
36 B 121 8 119 545
6 B 122 1 172 701
18 C 113
51 S 125 6 171 581
20 B 126 4 197 926
26 C 106
34 S 128 8 103 768
26 B 129 8 181 534
3 B 131 8 145 347
35 B 133 6 135 259
4 S 136 5 134 517
46 B 138 1 116 52
15 S 139 1 194 416
39 B 140 4 106 248
13 B 142 3 180 441
21 B 143 5 170 513
17 S 144 5 128 927
26 B 145 8 158 991
59 B 146 5 165 69
22 B 147 3 152 128
25 S 148 0 171 187
18 B 149 3 194 115
32 B 150 7 196 431
26 B 151 2 194 930
19 B 152 6 138 860
21 B 154 3 139 579
62 S 157 0 117 320
21 C 143
19 S 161 4 174 630
22 S 162 5 162 58
29 B 163 0 165 71
48 S 164 8 141 163
36 B 165 8 178 601
40 C 116
36 B 169 7 156 947
42 S 170 3 145 19
24 B 171 9 150 425
22 B 173 7 101 281
5 C 112
15 B 175 5 192 686
25 B 176 7 105 113
25 S 177 4 106 508
48 S 178 4 117 675
45 S 179 2 153 317
43 B 180 7 199 488
31 B 181 7 200 88
4 S 182 6 108 25
43 S 183 9 134 341
0 B 184 4 123 711
18 C 118
28 B 186 2 130 538
35 C 133
54 B 188 5 182 69
20 S 189 8 123 366
59 C 146
54 B 191 9 172 750
54 B 192 3 110 377
48 S 193 3 195 248
39 B 194 8 143 582
42 C 170
18 C 118
27 B 198 8 154 373
35 C 133
15 B 201 9 140 974
40 B 202 9 123 724
42 C 170
40 B 204 1 187 538
35 C 133
27 C 198
17 C 144
16 S 208 5 152 164
51 B 209 6 107 142
52 S 210 6 187 779
31 S 211 2 146 990
3 C 131
32 S 213 9 193 296
51 S 214 3 125 838
31 C 211
31 B 216 8 139 899
54 S 217 5 142 49
48 S 218 9 120 787
12 S 219 8 143 356
21 S 220 9 195 764
36 C 121
16 B 222 4 132 352
17 S 224 4 115 890
49 S 225 2 138 797
8 B 227 9 178 571
45 B 228 2 150 693
5 S 229 3 159 306
0 C 184
59 C 146
2 B 234 6 154 807
40 S 235 5 117 130
9 S 236 8 199 424
30 B 237 1 143 975
37 S 238 9 145 946
41 B 239 3 187 78
52 B 240 9 166 231
52 C 240
26 B 242 4 155 960
29 S 243 0 151 489
7 S 244 3 133 921
50 S 245 6 128 508
50 B 246 2 199 156
4 C 182
63 B 248 0 161 926
22 S 249 8 175 488
28 B 250 3 188 487
39 C 140
23 S 252 5 107 481
27 C 198
40 S 254 6 184 220
4 C 136
40 B 257 1 155 148
43 B 258 7 179 589
13 C 142
58 B 261 7 176 363
26 C 129
24 B 263 6 138 793
5 C 112
34 S 265 3 137 399
27 C 198
51 S 267 1 178 45
1 S 268 1 176 55
2 C 234
28 S 270 7 108 26
60 S 271 7 196 354
32 B 272 0 173 642
61 S 273 8 173 74
2 C 234
5 S 275 3 172 397
53 S 276 3 170 715
59 B 277 1 106 866
23 C 252
46 C 138
49 C 225
17 S 281 3 197 328
25 C 176
9 B 283 1 138 562
5 C 229
37 B 285 5 105 744
56 B 286 7 189 97
41 B 287 3 146 961
19 C 161
60 C 271
52 C 210
44 S 291 9 131 501
17 S 293 2 186 984
13 S 294 3 198 632
44 B 295 1 114 379
54 S 296 3 152 454
59 S 297 2 122 39
6 C 122
44 C 291
52 C 210
1 C 103
14 S 302 0 197 90
7 B 303 0 136 70
62 B 304 8 146 18
46 S 305 2 179 892
44 C 291
22 B 307 9 183 794
28 S 308 0 189 140
34 B 309 4 179 907
16 B 310 6 200 998
31 C 181
44 S 313 8 181 477
40 S 314 4 147 987
57 S 315 9 182 893
49 S 316 1 157 230
13 C 142
8 S 319 8 194 993
52 C 240
19 S 321 3 116 297
0 C 184
50 S 323 7 186 865
17 B 324 4 100 408
20 C 126
26 S 326 9 194 931
41 C 239
11 S 328 5 130 682
25 C 148
2 B 330 4 132 93
3 B 331 6 138 169
3 C 331
41 S 333 9 196 808
23 S 334 9 167 961
53 B 335 2 116 159
56 C 286
37 S 337 2 108 952
57 S 338 0 135 931
22 C 147
40 C 235
20 B 341 3 108 457
43 S 342 4 108 29
31 S 343 5 146 62
15 B 344 1 111 196
15 B 345 2 197 351
3 B 346 3 159 932
40 B 347 4 147 433
39 B 348 7 142 884
39 C 194
16 S 350 1 100 141
4 S 352 7 170 487
22 C 249
22 C 147
62 B 355 0 103 459
48 B 356 6 174 389
41 S 357 7 138 99
41 S 358 5 189 38
20 B 359 2 188 626
59 C 277
2 B 361 8 157 386
24 C 111
28 S 363 9 123 866
52 S 364 4 169 716
54 B 365 1 146 912
8 S 366 8 109 968
24 S 367 7 200 983
22 B 368 3 180 119
5 S 369 1 124 372
58 S 370 1 100 787
15 B 371 8 136 821
17 B 372 3 156 693
3 B 373 2 100 808
16 B 374 2 104 871
7 S 375 5 131 775
31 B 376 1 105 939
18 B 377 6 148 874
25 C 176
9 S 379 1 169 973
24 C 111
6 B 381 8 165 105
25 C 148
58 B 383 9 194 421
38 S 384 6 118 674
39 B 385 7 191 917
51 C 267
60 S 387 0 107 318
62 C 355
11 C 328
50 S 390 5 127 761
61 C 273
53 B 392 9 177 842
43 C 183
5 S 394 8 199 471
57 B 395 2 159 760
16 B 396 3 176 386
48 C 356
38 C 384
33 S 399 7 129 19
34 C 309
60 C 271
4 C 182
4 C 352
44 C 105
42 S 405 4 144 647
49 S 406 6 137 352
62 S 407 5 178 127
33 S 408 0 136 552
63 B 409 5 169 252
8 B 410 6 162 683
47 B 411 6 155 689
32 S 412 2 169 909
0 C 184
6 B 414 0 186 255
63 S 415 5 190 797
4 B 416 9 137 788
0 S 417 9 182 62
4 S 418 1 109 242
51 S 419 1 104 23
54 C 192
33 S 421 6 114 808
7 C 303
18 C 377
17 C 293
14 B 425 7 199 509
60 C 271
58 C 383
14 C 302
3 C 346
43 C 258
6 B 431 7 134 222
32 B 432 4 134 283
52 S 433 4 195 345
57 C 315
36 C 165
3 S 436 1 133 936
19 S 437 0 185 117
7 B 438 5 100 34
43 B 439 8 152 77
14 S 440 2 113 689
40 B 441 1 166 936
19 S 442 2 186 71
38 C 384
9 B 444 5 102 374
7 C 438
24 C 171
52 C 210
61 B 448 2 194 51
24 C 263
20 S 450 5 136 355
56 C 286
60 B 452 0 140 312
37 B 453 5 193 251
37 B 454 4 120 572
1 S 455 3 136 681
44 C 105
54 S 457 1 182 613
25 B 458 5 163 721
12 S 459 9 153 611
45 S 460 0 124 706
28 C 186
0 C 184
12 C 219
59 B 464 8 166 596
31 B 465 1 153 753
62 B 466 9 143 382
20 S 467 0 119 432
47 B 468 9 161 553
61 S 469 6 140 151
3 B 470 0 197 227
39 B 471 4 159 707
52 B 472 5 137 961
24 B 473 1 147 811
51 S 474 5 130 554
8 C 410
26 S 476 6 200 425
39 C 385
39 S 478 9 168 26
18 C 149
25 B 480 3 183 429
56 B 481 5 184 331
24 C 111
63 B 483 5 188 123
17 C 372
33 C 408
22 B 486 2 127 765
52 S 487 8 119 436
48 B 488 3 118 396
24 S 489 1 173 91
46 C 305
2 C 234
3 C 373
63 C 415
47 C 468
31 B 495 5 141 746
19 S 496 7 170 272
52 B 497 4 143 970
50 S 498 4 141 27
56 C 481
53 C 392
17 S 501 2 178 532
43 C 102
58 C 261
42 C 405
40 S 505 6 181 104
34 S 506 4 137 311
60 C 452
56 S 508 4 110 640
16 C 310
18 S 510 2 144 473
34 B 511 7 137 426
37 S 512 6 196 577
1 C 103
2 S 514 8 197 615
8 S 515 9 164 336
56 S 516 3 196 931
15 C 139
2 B 518 8 157 805
53 C 276
51 B 520 4 148 928
57 C 395
59 S 522 6 163 815
34 S 523 6 171 403
19 B 524 2 119 448
61 B 525 9 145 383
0 S 526 2 200 472
42 S 527 0 121 810
49 S 528 0 123 839
60 B 529 0 109 114
23 S 530 2 118 424
46 C 138
6 B 532 1 133 338
4 S 533 3 148 111
55 S 534 6 127 948
63 C 248
47 S 536 6 183 906
60 S 537 3 115 998
11 B 538 6 181 877
37 B 539 6 130 996
60 C 387
5 B 541 9 153 603
1 S 542 5 155 530
50 C 390
12 S 544 1 186 851
5 S 545 7 138 474
12 S 546 9 161 144
21 B 547 2 105 604
63 S 548 7 166 862
18 B 549 1 120 151
44 B 550 9 132 757
23 C 334
60 C 529
61 S 553 1 164 226
40 B 554 0 154 586
60 C 387
15 B 556 5 111 261
63 B 557 4 190 86
39 S 558 7 161 88
4 S 559 0 189 457
31 C 181
28 C 186
57 B 562 3 163 197
41 C 358
6 S 564 4 125 846
14 B 565 8 174 13
13 C 142
7 B 567 1 100 414
29 B 568 1 193 345
40 B 569 0 157 523
18 S 570 6 181 969
30 S 571 6 118 436
44 S 572 0 143 497
1 C 455
13 B 574 3 152 804
18 C 113
47 C 536
62 B 577 8 124 37
50 S 578 9 106 357
39 S 579 1 197 609
12 C 546
7 B 581 5 103 177
26 B 582 7 187 750
49 S 583 9 155 460
9 S 584 8 132 206
19 C 496
54 S 586 4 150 297
11 B 587 0 135 69
31 S 588 1 175 301
24 B 589 5 199 306
2 C 330
52 C 487
47 C 468
41 C 358
35 C 133
18 S 595 2 124 751
43 C 342
39 C 478
3 B 598 1 186 539
2 S 599 0 110 453
14 C 425
16 B 601 8 134 916
47 S 602 0 187 985
58 B 603 1 183 16
17 S 604 8 165 468
44 C 295
41 C 239
48 S 607 4 166 521
58 S 608 6 139 278
28 B 609 7 173 120
1 B 610 4 131 978
30 B 611 0 121 402
22 S 612 7 123 614
29 C 568
29 S 614 7 146 245
30 S 615 2 133 355
17 S 616 6 116 418
23 B 617 7 120 480
60 S 618 0 149 832
28 C 609
43 B 620 1 152 756
3 S 621 0 128 163
54 B 622 8 174 275
53 C 276
30 C 237
15 C 175
5 B 626 9 151 726
28 B 627 9 125 39
0 B 628 1 188 646
23 C 617
26 B 630 4 178 743
41 S 631 4 176 937
50 S 632 0 130 904
63 B 633 4 103 730
24 B 634 3 157 950
19 C 161
1 B 636 9 185 857
4 B 637 3 140 643
33 S 638 4 109 731
7 S 639 5 111 317
58 S 640 6 106 447
10 B 641 2 103 973
